data/output-ground-truth/ABBN.txt
PASSIVE BUY 2260.00 @ 49.68
PASSIVE BUY 2380.00 @ 49.83
PASSIVE BUY 1540.00 @ 49.74
PASSIVE BUY 780.00 @ 49.74
PASSIVE SELL 580.00 @ 50.27
PASSIVE BUY 2580.00 @ 49.81
PASSIVE SELL 2060.00 @ 50.16
PASSIVE SELL 1220.00 @ 50.02
PASSIVE BUY 1060.00 @ 49.82
PASSIVE SELL 1100.00 @ 50.04
PASSIVE SELL 1300.00 @ 50.12
PASSIVE SELL 1340.00 @ 49.84
AGGRESSIVE BUY 1860.00 @ 49.87
PASSIVE BUY 1820.00 @ 49.90
CANCEL BUY 2260.00 @ 49.68
CANCEL BUY 2380.00 @ 49.83
CANCEL BUY -1540.00 @ 49.74
CANCEL BUY 780.00 @ 49.74
CANCEL BUY 2580.00 @ 49.81
CANCEL BUY 1060.00 @ 49.82
CANCEL BUY 520.00 @ 49.87
CANCEL BUY 1820.00 @ 49.90
PASSIVE SELL 1940.00 @ 50.13
PASSIVE BUY 940.00 @ 50.01
PASSIVE BUY 900.00 @ 49.89
AGGRESSIVE SELL 1180.00 @ 49.97
CANCEL SELL 580.00 @ 50.27
AGGRESSIVE BUY 980.00 @ 50.02
PASSIVE BUY 2100.00 @ 49.94
PASSIVE SELL 900.00 @ 50.07
AGGRESSIVE BUY 2500.00 @ 50.02
PASSIVE BUY 1820.00 @ 49.94
AGGRESSIVE BUY 1540.00 @ 50.07
PASSIVE BUY 2220.00 @ 49.97
AGGRESSIVE BUY 1860.00 @ 50.13
PASSIVE SELL 1580.00 @ 50.12
PASSIVE BUY 2220.00 @ 49.91
PASSIVE BUY 860.00 @ 50.01
AGGRESSIVE SELL 1660.00 @ 50.02
PASSIVE SELL 940.00 @ 50.14
PASSIVE BUY 1740.00 @ 50.07
CANCEL BUY 900.00 @ 49.89
CANCEL BUY -2100.00 @ 49.94
CANCEL BUY 360.00 @ 50.02
CANCEL BUY 1820.00 @ 49.94
CANCEL BUY 2220.00 @ 49.97
CANCEL BUY 2220.00 @ 49.91
CANCEL BUY 860.00 @ 50.01
CANCEL BUY 1740.00 @ 50.07
PASSIVE BUY 2540.00 @ 50.11
PASSIVE BUY 2860.00 @ 50.07
AGGRESSIVE BUY 2900.00 @ 50.13
PASSIVE SELL 1020.00 @ 50.19
PASSIVE BUY 2180.00 @ 50.05
PASSIVE SELL 1900.00 @ 50.16
PASSIVE BUY 2260.00 @ 50.01
PASSIVE BUY 820.00 @ 50.10
AGGRESSIVE BUY 2660.00 @ 50.16
AGGRESSIVE BUY 1340.00 @ 50.16
PASSIVE BUY 1820.00 @ 50.15
AGGRESSIVE BUY 860.00 @ 50.16
PASSIVE BUY 2060.00 @ 50.07
AGGRESSIVE BUY 2780.00 @ 50.16
CANCEL BUY 2540.00 @ 50.11
CANCEL BUY -2860.00 @ 50.07
CANCEL BUY 2180.00 @ 50.05
CANCEL BUY 2260.00 @ 50.01
CANCEL BUY 820.00 @ 50.10
CANCEL BUY 1820.00 @ 50.15
CANCEL BUY 2060.00 @ 50.07
CANCEL BUY 2220.00 @ 50.16
AGGRESSIVE BUY 2460.00 @ 50.20
AGGRESSIVE SELL 820.00 @ 50.20
AGGRESSIVE SELL 2220.00 @ 50.14
AGGRESSIVE BUY 1380.00 @ 50.14
PASSIVE BUY 1420.00 @ 49.95
PASSIVE SELL 1540.00 @ 50.11
PASSIVE BUY 1180.00 @ 49.90
AGGRESSIVE BUY 1220.00 @ 50.11
PASSIVE BUY 1780.00 @ 50.02
PASSIVE BUY 2500.00 @ 49.94
PASSIVE BUY 1020.00 @ 49.94
PASSIVE BUY 2380.00 @ 49.94
PASSIVE BUY 2940.00 @ 50.00
PASSIVE SELL 820.00 @ 50.19
AGGRESSIVE BUY 740.00 @ 50.12
AGGRESSIVE SELL 1580.00 @ 50.09
AGGRESSIVE SELL 2260.00 @ 50.02
AGGRESSIVE BUY 1340.00 @ 50.06
AGGRESSIVE BUY 1820.00 @ 50.09
PASSIVE SELL 2300.00 @ 50.27
PASSIVE SELL 940.00 @ 50.12
PASSIVE BUY 1540.00 @ 49.95
PASSIVE SELL 1380.00 @ 50.22
PASSIVE SELL 660.00 @ 50.18
AGGRESSIVE BUY 1060.00 @ 50.14
AGGRESSIVE SELL 620.00 @ 50.09
PASSIVE BUY 1820.00 @ 50.11
CANCEL BUY -1420.00 @ 49.95
CANCEL BUY 1180.00 @ 49.90
CANCEL BUY -2500.00 @ 49.94
CANCEL BUY -1020.00 @ 49.94
CANCEL BUY 2380.00 @ 49.94
CANCEL BUY 2940.00 @ 50.00
CANCEL BUY 860.00 @ 50.06
CANCEL BUY 40.00 @ 50.09
CANCEL BUY 1540.00 @ 49.95
CANCEL BUY 1820.00 @ 50.11
PASSIVE SELL 1940.00 @ 50.15
PASSIVE BUY 1300.00 @ 50.10
PASSIVE SELL 1260.00 @ 50.14
PASSIVE BUY 820.00 @ 49.98
PASSIVE BUY 2620.00 @ 49.98
PASSIVE SELL 940.00 @ 50.19
PASSIVE SELL 1540.00 @ 50.14
AGGRESSIVE BUY 1900.00 @ 50.14
PASSIVE SELL 1020.00 @ 50.20
CANCEL SELL 2300.00 @ 50.27
PASSIVE SELL 740.00 @ 50.25
CANCEL SELL 740.00 @ 50.25
PASSIVE BUY 1900.00 @ 50.03
AGGRESSIVE BUY 1300.00 @ 50.15
PASSIVE SELL 1900.00 @ 50.25
AGGRESSIVE SELL 1420.00 @ 50.03
AGGRESSIVE BUY 1260.00 @ 50.15
PASSIVE BUY 2780.00 @ 50.04
PASSIVE SELL 420.00 @ 50.14
CANCEL SELL 1900.00 @ 50.25
PASSIVE BUY 1980.00 @ 50.06
PASSIVE SELL 2100.00 @ 50.13
CANCEL SELL 1380.00 @ 50.22
PASSIVE SELL 460.00 @ 50.21
CANCEL SELL 460.00 @ 50.21
AGGRESSIVE SELL 1380.00 @ 50.06
AGGRESSIVE SELL 700.00 @ 50.04
PASSIVE SELL 980.00 @ 50.18
AGGRESSIVE BUY 2100.00 @ 50.13
PASSIVE SELL 2140.00 @ 50.06
AGGRESSIVE BUY 2540.00 @ 50.14
AGGRESSIVE BUY 2420.00 @ 50.15
AGGRESSIVE SELL 1260.00 @ 50.15
PASSIVE BUY 2100.00 @ 50.06
AGGRESSIVE BUY 2460.00 @ 50.19
AGGRESSIVE BUY 1660.00 @ 50.20
AGGRESSIVE SELL 1500.00 @ 50.07
PASSIVE BUY 1860.00 @ 50.01
PASSIVE SELL 1140.00 @ 50.10
AGGRESSIVE BUY 1060.00 @ 50.10
AGGRESSIVE SELL 1660.00 @ 50.06
PASSIVE SELL 1540.00 @ 50.18
AGGRESSIVE BUY 1460.00 @ 50.12
PASSIVE SELL 820.00 @ 50.30
AGGRESSIVE BUY 940.00 @ 50.18
PASSIVE SELL 820.00 @ 50.14
AGGRESSIVE SELL 2260.00 @ 50.11
AGGRESSIVE BUY 860.00 @ 50.11
PASSIVE BUY 860.00 @ 50.06
PASSIVE SELL 1540.00 @ 50.13
PASSIVE BUY 2740.00 @ 50.10
AGGRESSIVE BUY 2820.00 @ 50.14
AGGRESSIVE BUY 2420.00 @ 50.22
CANCEL BUY -820.00 @ 49.98
CANCEL BUY 2620.00 @ 49.98
CANCEL BUY 1780.00 @ 50.03
CANCEL BUY 2680.00 @ 50.04
CANCEL BUY -440.00 @ 50.06
CANCEL BUY 1860.00 @ 50.01
CANCEL BUY 860.00 @ 50.06
CANCEL BUY 2740.00 @ 50.10
CANCEL BUY 1220.00 @ 50.22
PASSIVE BUY 2260.00 @ 50.27
PASSIVE BUY 2580.00 @ 50.17
AGGRESSIVE BUY 1260.00 @ 50.35
PASSIVE BUY 2900.00 @ 50.46
PASSIVE BUY 1860.00 @ 50.60
AGGRESSIVE SELL 1380.00 @ 50.60
PASSIVE BUY 1700.00 @ 50.71
PASSIVE BUY 1020.00 @ 50.72
CANCEL BUY 2260.00 @ 50.27
CANCEL BUY 2580.00 @ 50.17
CANCEL BUY 440.00 @ 50.35
CANCEL BUY 2900.00 @ 50.46
CANCEL BUY 480.00 @ 50.60
CANCEL BUY 1700.00 @ 50.71
CANCEL BUY 1020.00 @ 50.72
PASSIVE BUY 860.00 @ 49.94
PASSIVE BUY 1140.00 @ 49.82
PASSIVE BUY 2860.00 @ 49.90
PASSIVE BUY 1300.00 @ 49.96
PASSIVE SELL 1700.00 @ 50.53
PASSIVE BUY 820.00 @ 49.99
PASSIVE SELL 580.00 @ 50.45
PASSIVE SELL 2220.00 @ 50.55
PASSIVE BUY 940.00 @ 49.92
PASSIVE SELL 940.00 @ 50.31
PASSIVE BUY 1940.00 @ 50.10
CANCEL BUY 860.00 @ 49.94
CANCEL BUY 1140.00 @ 49.82
CANCEL BUY 2860.00 @ 49.90
CANCEL BUY 1300.00 @ 49.96
CANCEL BUY 820.00 @ 49.99
CANCEL BUY 940.00 @ 49.92
CANCEL BUY 1940.00 @ 50.10
PASSIVE BUY 2100.00 @ 50.17
PASSIVE BUY 1100.00 @ 50.19
PASSIVE BUY 900.00 @ 50.24
AGGRESSIVE BUY 1820.00 @ 50.36
PASSIVE BUY 1300.00 @ 50.44
PASSIVE BUY 2660.00 @ 50.41
PASSIVE SELL 380.00 @ 50.48
AGGRESSIVE BUY 2780.00 @ 50.55
PASSIVE BUY 2380.00 @ 50.33
CANCEL BUY 2100.00 @ 50.17
CANCEL BUY 1100.00 @ 50.19
CANCEL BUY 900.00 @ 50.24
CANCEL BUY 880.00 @ 50.36
CANCEL BUY 1300.00 @ 50.44
CANCEL BUY 2660.00 @ 50.41
CANCEL BUY 2380.00 @ 50.33
PASSIVE SELL 1020.00 @ 50.56
PASSIVE SELL 2100.00 @ 50.63
PASSIVE SELL 1020.00 @ 50.59
AGGRESSIVE BUY 1860.00 @ 50.55
PASSIVE SELL 1140.00 @ 50.38
PASSIVE SELL 1780.00 @ 50.27
PASSIVE SELL 780.00 @ 50.22
CANCEL SELL 2100.00 @ 50.63
AGGRESSIVE BUY 2620.00 @ 50.38
AGGRESSIVE BUY 1540.00 @ 50.49
PASSIVE SELL 1300.00 @ 50.66
AGGRESSIVE BUY 2700.00 @ 50.64
AGGRESSIVE BUY 2940.00 @ 50.68
PASSIVE BUY 1420.00 @ 50.58
PASSIVE BUY 740.00 @ 50.83
PASSIVE BUY 740.00 @ 50.71
PASSIVE BUY 2780.00 @ 50.76
CANCEL BUY 460.00 @ 50.49
CANCEL BUY 420.00 @ 50.64
CANCEL BUY 1640.00 @ 50.68
CANCEL BUY 1420.00 @ 50.58
CANCEL BUY 740.00 @ 50.83
CANCEL BUY 740.00 @ 50.71
CANCEL BUY 2780.00 @ 50.76
PASSIVE SELL 2260.00 @ 50.81
PASSIVE BUY 1260.00 @ 50.66
PASSIVE BUY 1220.00 @ 50.69
AGGRESSIVE SELL 1540.00 @ 50.66
PASSIVE BUY 2300.00 @ 50.68
PASSIVE SELL 1540.00 @ 50.83
PASSIVE BUY 940.00 @ 50.75
AGGRESSIVE BUY 2700.00 @ 50.83
PASSIVE BUY 1660.00 @ 50.77
PASSIVE BUY 900.00 @ 50.74
PASSIVE SELL 1100.00 @ 50.81
AGGRESSIVE SELL 1260.00 @ 50.77
PASSIVE BUY 1340.00 @ 50.67
AGGRESSIVE SELL 580.00 @ 50.75
AGGRESSIVE SELL 1660.00 @ 50.74
AGGRESSIVE BUY 2020.00 @ 50.82
AGGRESSIVE SELL 2020.00 @ 50.82
PASSIVE SELL 1580.00 @ 50.76
PASSIVE BUY 2940.00 @ 50.65
PASSIVE BUY 1740.00 @ 50.58
PASSIVE BUY 1300.00 @ 50.63
PASSIVE SELL 1740.00 @ 50.72
PASSIVE BUY 2380.00 @ 50.71
CANCEL BUY 940.00 @ 50.66
CANCEL BUY 2300.00 @ 50.68
CANCEL BUY 1340.00 @ 50.67
CANCEL BUY 2940.00 @ 50.65
CANCEL BUY 1740.00 @ 50.58
CANCEL BUY 1300.00 @ 50.63
CANCEL BUY 2380.00 @ 50.71
AGGRESSIVE BUY 1900.00 @ 50.72
PASSIVE SELL 620.00 @ 50.79
PASSIVE SELL 900.00 @ 50.83
AGGRESSIVE BUY 1420.00 @ 50.76
AGGRESSIVE BUY 2220.00 @ 50.81
AGGRESSIVE SELL 2180.00 @ 50.79
PASSIVE BUY 2620.00 @ 50.69
AGGRESSIVE SELL 2220.00 @ 50.69
