data/output-ground-truth/NESN.txt
PASSIVE SELL 1460.00 @ 101.11
PASSIVE SELL 740.00 @ 101.15
PASSIVE SELL 780.00 @ 100.99
PASSIVE BUY 1420.00 @ 100.76
PASSIVE BUY 2700.00 @ 100.64
PASSIVE BUY 2500.00 @ 100.86
PASSIVE SELL 500.00 @ 100.91
PASSIVE BUY 2740.00 @ 100.87
AGGRESSIVE SELL 1220.00 @ 100.87
PASSIVE SELL 1540.00 @ 100.93
PASSIVE BUY 2260.00 @ 100.86
AGGRESSIVE SELL 1620.00 @ 100.86
AGGRESSIVE SELL 1540.00 @ 100.86
PASSIVE BUY 1660.00 @ 100.87
AGGRESSIVE BUY 1780.00 @ 100.93
PASSIVE BUY 2540.00 @ 100.91
PASSIVE BUY 2460.00 @ 100.79
PASSIVE BUY 1900.00 @ 100.83
CANCEL BUY 1420.00 @ 100.76
CANCEL BUY 2700.00 @ 100.64
CANCEL BUY -860.00 @ 100.86
CANCEL BUY 2260.00 @ 100.86
CANCEL BUY 1660.00 @ 100.87
CANCEL BUY 2540.00 @ 100.91
CANCEL BUY 2460.00 @ 100.79
CANCEL BUY 1900.00 @ 100.83
PASSIVE BUY 1980.00 @ 100.75
PASSIVE BUY 2060.00 @ 100.86
PASSIVE BUY 2020.00 @ 100.84
AGGRESSIVE SELL 460.00 @ 100.86
AGGRESSIVE SELL 1700.00 @ 100.84
PASSIVE SELL 700.00 @ 100.87
AGGRESSIVE BUY 2420.00 @ 100.88
AGGRESSIVE SELL 420.00 @ 100.88
AGGRESSIVE SELL 740.00 @ 100.88
AGGRESSIVE BUY 2100.00 @ 100.97
AGGRESSIVE SELL 1260.00 @ 100.97
PASSIVE BUY 1540.00 @ 100.97
AGGRESSIVE BUY 2860.00 @ 101.09
PASSIVE SELL 2300.00 @ 101.11
AGGRESSIVE SELL 700.00 @ 101.09
AGGRESSIVE BUY 1420.00 @ 101.11
PASSIVE BUY 2420.00 @ 101.01
AGGRESSIVE BUY 2220.00 @ 101.11
AGGRESSIVE SELL 1980.00 @ 101.08
AGGRESSIVE SELL 1300.00 @ 101.01
PASSIVE SELL 1100.00 @ 101.05
AGGRESSIVE BUY 1820.00 @ 101.09
PASSIVE SELL 1140.00 @ 101.23
PASSIVE BUY 2900.00 @ 101.07
CANCEL BUY 1980.00 @ 100.75
CANCEL BUY 1920.00 @ 100.84
CANCEL BUY 560.00 @ 100.88
CANCEL BUY -580.00 @ 100.97
CANCEL BUY 1540.00 @ 100.97
CANCEL BUY 1120.00 @ 101.01
CANCEL BUY 120.00 @ 101.09
CANCEL BUY 2900.00 @ 101.07
AGGRESSIVE BUY 2740.00 @ 101.19
PASSIVE SELL 900.00 @ 101.23
PASSIVE BUY 2300.00 @ 101.09
AGGRESSIVE SELL 1580.00 @ 101.19
PASSIVE BUY 2220.00 @ 101.09
AGGRESSIVE BUY 1180.00 @ 101.23
AGGRESSIVE BUY 900.00 @ 101.30
AGGRESSIVE SELL 1340.00 @ 101.25
PASSIVE BUY 1340.00 @ 101.19
AGGRESSIVE SELL 1580.00 @ 101.19
PASSIVE BUY 2660.00 @ 101.12
PASSIVE SELL 1140.00 @ 101.25
PASSIVE SELL 1060.00 @ 101.23
PASSIVE SELL 1060.00 @ 101.33
PASSIVE SELL 1540.00 @ 101.29
AGGRESSIVE BUY 2340.00 @ 101.24
AGGRESSIVE BUY 1820.00 @ 101.25
PASSIVE SELL 980.00 @ 101.29
PASSIVE BUY 1740.00 @ 101.13
PASSIVE SELL 1140.00 @ 101.26
AGGRESSIVE BUY 1380.00 @ 101.26
AGGRESSIVE SELL 1020.00 @ 101.24
AGGRESSIVE BUY 2220.00 @ 101.29
PASSIVE SELL 1700.00 @ 101.30
PASSIVE BUY 2420.00 @ 101.16
AGGRESSIVE BUY 2860.00 @ 101.33
AGGRESSIVE BUY 820.00 @ 101.33
CANCEL BUY -2300.00 @ 101.09
CANCEL BUY 2220.00 @ 101.09
CANCEL BUY 60.00 @ 101.19
CANCEL BUY 2660.00 @ 101.12
CANCEL BUY 260.00 @ 101.24
CANCEL BUY 1740.00 @ 101.13
CANCEL BUY 2420.00 @ 101.16
CANCEL BUY 240.00 @ 101.33
PASSIVE BUY 980.00 @ 100.93
PASSIVE SELL 1420.00 @ 101.24
PASSIVE SELL 1860.00 @ 101.10
PASSIVE SELL 1420.00 @ 101.04
PASSIVE BUY 1220.00 @ 100.87
PASSIVE SELL 1980.00 @ 100.96
AGGRESSIVE SELL 1180.00 @ 100.87
PASSIVE BUY 2020.00 @ 100.76
PASSIVE SELL 1740.00 @ 100.95
PASSIVE SELL 1660.00 @ 101.06
PASSIVE SELL 980.00 @ 101.07
CANCEL SELL 1420.00 @ 101.24
PASSIVE SELL 2220.00 @ 101.00
CANCEL SELL 1860.00 @ 101.10
PASSIVE SELL 1740.00 @ 100.94
CANCEL SELL 980.00 @ 101.07
AGGRESSIVE SELL 1340.00 @ 100.86
CANCEL SELL 1660.00 @ 101.06
PASSIVE BUY 2500.00 @ 100.73
PASSIVE BUY 2740.00 @ 100.72
AGGRESSIVE SELL 1820.00 @ 100.76
PASSIVE SELL 740.00 @ 100.80
CANCEL SELL 1420.00 @ 101.04
PASSIVE SELL 2060.00 @ 100.78
CANCEL SELL 2220.00 @ 101.00
AGGRESSIVE SELL 1020.00 @ 100.73
PASSIVE SELL 780.00 @ 100.88
CANCEL SELL 1980.00 @ 100.96
PASSIVE BUY 1860.00 @ 100.73
PASSIVE BUY 2260.00 @ 100.71
AGGRESSIVE SELL 2100.00 @ 100.73
PASSIVE SELL 1140.00 @ 100.90
CANCEL SELL 1740.00 @ 100.95
PASSIVE SELL 1340.00 @ 100.74
CANCEL SELL 1740.00 @ 100.94
AGGRESSIVE BUY 1620.00 @ 100.78
PASSIVE BUY 1500.00 @ 100.75
PASSIVE BUY 2380.00 @ 100.63
AGGRESSIVE SELL 1220.00 @ 100.75
AGGRESSIVE BUY 1260.00 @ 100.78
PASSIVE SELL 1460.00 @ 100.80
PASSIVE BUY 1340.00 @ 100.75
AGGRESSIVE BUY 1060.00 @ 100.78
AGGRESSIVE BUY 1580.00 @ 100.80
AGGRESSIVE BUY 2180.00 @ 100.81
CANCEL BUY 2740.00 @ 100.72
CANCEL BUY 1440.00 @ 100.73
CANCEL BUY 2260.00 @ 100.71
CANCEL BUY -280.00 @ 100.75
CANCEL BUY 2380.00 @ 100.63
CANCEL BUY 1340.00 @ 100.75
CANCEL BUY 540.00 @ 100.78
CANCEL BUY 1560.00 @ 100.81
AGGRESSIVE BUY 2740.00 @ 100.94
PASSIVE BUY 1540.00 @ 101.07
PASSIVE BUY 2940.00 @ 101.25
AGGRESSIVE SELL 860.00 @ 101.25
PASSIVE BUY 2140.00 @ 101.26
PASSIVE BUY 2140.00 @ 101.30
PASSIVE BUY 1900.00 @ 101.26
AGGRESSIVE SELL 1100.00 @ 101.30
PASSIVE BUY 2460.00 @ 101.34
PASSIVE BUY 2180.00 @ 101.31
CANCEL BUY 500.00 @ 100.94
CANCEL BUY 1540.00 @ 101.07
CANCEL BUY 2080.00 @ 101.25
CANCEL BUY -2140.00 @ 101.26
CANCEL BUY 1040.00 @ 101.30
CANCEL BUY 1900.00 @ 101.26
CANCEL BUY 2460.00 @ 101.34
CANCEL BUY 2180.00 @ 101.31
PASSIVE BUY 1100.00 @ 100.79
PASSIVE SELL 1020.00 @ 100.96
PASSIVE SELL 1300.00 @ 100.85
AGGRESSIVE BUY 1620.00 @ 100.89
PASSIVE SELL 860.00 @ 101.04
PASSIVE BUY 2900.00 @ 100.85
PASSIVE BUY 1820.00 @ 100.92
PASSIVE SELL 1540.00 @ 100.96
AGGRESSIVE SELL 540.00 @ 100.92
AGGRESSIVE BUY 2020.00 @ 100.96
PASSIVE BUY 2420.00 @ 100.86
PASSIVE BUY 2700.00 @ 100.84
AGGRESSIVE BUY 2700.00 @ 100.98
CANCEL BUY 1100.00 @ 100.79
CANCEL BUY 320.00 @ 100.89
CANCEL BUY 2900.00 @ 100.85
CANCEL BUY 1280.00 @ 100.92
CANCEL BUY 2420.00 @ 100.86
CANCEL BUY 2700.00 @ 100.84
CANCEL BUY 2160.00 @ 100.98
PASSIVE SELL 1180.00 @ 101.13
PASSIVE SELL 380.00 @ 101.12
PASSIVE BUY 2660.00 @ 100.90
PASSIVE SELL 2300.00 @ 100.91
AGGRESSIVE BUY 2460.00 @ 101.02
PASSIVE SELL 1180.00 @ 101.17
AGGRESSIVE SELL 1540.00 @ 100.95
PASSIVE SELL 1260.00 @ 100.98
AGGRESSIVE BUY 2420.00 @ 100.98
AGGRESSIVE SELL 1220.00 @ 100.90
PASSIVE SELL 2140.00 @ 100.94
PASSIVE SELL 940.00 @ 101.01
CANCEL SELL 1180.00 @ 101.17
AGGRESSIVE BUY 2460.00 @ 101.01
AGGRESSIVE BUY 1980.00 @ 101.08
PASSIVE BUY 1860.00 @ 101.04
PASSIVE BUY 1060.00 @ 100.99
AGGRESSIVE BUY 1420.00 @ 101.13
AGGRESSIVE BUY 2140.00 @ 101.22
PASSIVE BUY 2540.00 @ 101.15
PASSIVE SELL 1740.00 @ 101.38
PASSIVE BUY 1860.00 @ 101.12
CANCEL BUY 1440.00 @ 100.90
CANCEL BUY 280.00 @ 101.08
CANCEL BUY 1860.00 @ 101.04
CANCEL BUY 1060.00 @ 100.99
CANCEL BUY 2000.00 @ 101.22
CANCEL BUY 2540.00 @ 101.15
CANCEL BUY 1860.00 @ 101.12
AGGRESSIVE BUY 1580.00 @ 101.38
PASSIVE SELL 1500.00 @ 101.35
AGGRESSIVE BUY 860.00 @ 101.35
PASSIVE SELL 1180.00 @ 101.23
PASSIVE SELL 1020.00 @ 101.12
PASSIVE SELL 2180.00 @ 101.21
PASSIVE SELL 980.00 @ 101.19
AGGRESSIVE BUY 2460.00 @ 101.21
AGGRESSIVE BUY 1300.00 @ 101.21
PASSIVE SELL 1620.00 @ 101.28
PASSIVE SELL 1140.00 @ 101.07
PASSIVE SELL 700.00 @ 101.07
PASSIVE SELL 2220.00 @ 101.04
CANCEL SELL 160.00 @ 101.38
AGGRESSIVE BUY 1700.00 @ 101.04
PASSIVE SELL 740.00 @ 100.96
CANCEL SELL 640.00 @ 101.35
AGGRESSIVE BUY 1340.00 @ 101.07
AGGRESSIVE BUY 820.00 @ 101.07
AGGRESSIVE BUY 1660.00 @ 101.23
AGGRESSIVE BUY 1540.00 @ 101.28
PASSIVE BUY 2100.00 @ 101.24
AGGRESSIVE BUY 740.00 @ 101.28
AGGRESSIVE SELL 2180.00 @ 101.22
PASSIVE SELL 2100.00 @ 101.33
PASSIVE SELL 580.00 @ 101.18
PASSIVE SELL 1620.00 @ 101.12
PASSIVE SELL 2220.00 @ 101.20
AGGRESSIVE BUY 2740.00 @ 101.20
AGGRESSIVE BUY 2020.00 @ 101.22
PASSIVE BUY 1220.00 @ 101.22
PASSIVE SELL 900.00 @ 101.34
PASSIVE BUY 1500.00 @ 101.13
AGGRESSIVE BUY 1700.00 @ 101.33
AGGRESSIVE BUY 1780.00 @ 101.34
PASSIVE BUY 2340.00 @ 101.48
AGGRESSIVE SELL 2020.00 @ 101.48
AGGRESSIVE SELL 1220.00 @ 101.27
AGGRESSIVE BUY 1660.00 @ 101.30
PASSIVE BUY 940.00 @ 101.25
PASSIVE SELL 2300.00 @ 101.47
PASSIVE SELL 1140.00 @ 101.48
PASSIVE BUY 1580.00 @ 101.19
PASSIVE BUY 740.00 @ 101.43
AGGRESSIVE BUY 1980.00 @ 101.47
PASSIVE BUY 2140.00 @ 101.38
CANCEL BUY -260.00 @ 101.22
CANCEL BUY 1220.00 @ 101.22
CANCEL BUY 1500.00 @ 101.13
CANCEL BUY 1020.00 @ 101.30
CANCEL BUY 940.00 @ 101.25
CANCEL BUY 1580.00 @ 101.19
CANCEL BUY 740.00 @ 101.43
CANCEL BUY 2140.00 @ 101.38
PASSIVE BUY 1940.00 @ 101.34
AGGRESSIVE SELL 540.00 @ 101.34
